Traceback (most recent call last):
  File "D:\PycharmProjects\MyReinFlow\scripts\train.py", line 65, in main
    minari_dataset = minari.load_dataset(args.dataset)
  File "C:\Users\32293\.conda\envs\xuance\lib\site-packages\minari\storage\local.py", line 51, in load_dataset
    raise FileNotFoundError(
FileNotFoundError: Dataset mujoco/pusher/medium-v0 not found locally at C:\Users\32293\.minari\datasets\mujoco\pusher\medium-v0. Use download=True to download the dataset.
During handling of the above exception, another exception occurred:
Traceback (most recent call last):
  File "D:\PycharmProjects\MyReinFlow\main.py", line 46, in <module>
    main()
  File "D:\PycharmProjects\MyReinFlow\main.py", line 31, in main
    train_main()
  File "D:\PycharmProjects\MyReinFlow\scripts\train.py", line 85, in main
    raise Exception("Could not load any dataset")
Exception: Could not load any dataset
Traceback (most recent call last):
  File "D:\PycharmProjects\MyReinFlow\scripts\train.py", line 65, in main
    minari_dataset = minari.load_dataset(args.dataset)
  File "C:\Users\32293\.conda\envs\xuance\lib\site-packages\minari\storage\local.py", line 51, in load_dataset
    raise FileNotFoundError(
FileNotFoundError: Dataset mujoco/pusher/medium-v0 not found locally at C:\Users\32293\.minari\datasets\mujoco\pusher\medium-v0. Use download=True to download the dataset.
During handling of the above exception, another exception occurred:
Traceback (most recent call last):
  File "D:\PycharmProjects\MyReinFlow\main.py", line 46, in <module>
    main()
  File "D:\PycharmProjects\MyReinFlow\main.py", line 31, in main
    train_main()
  File "D:\PycharmProjects\MyReinFlow\scripts\train.py", line 85, in main
    raise Exception("Could not load any dataset")
Exception: Could not load any dataset
Loading Minari dataset: mujoco/pusher/medium-v0
Error loading dataset mujoco/pusher/medium-v0: Dataset mujoco/pusher/medium-v0 not found locally at C:\Users\32293\.minari\datasets\mujoco\pusher\medium-v0. Use download=True to download the dataset.
Trying to load a fallback dataset...
Trying fallback dataset: hopper-medium-v2
Failed to load hopper-medium-v2: Dataset hopper-medium-v2 not found locally at C:\Users\32293\.minari\datasets\hopper-medium-v2. Use download=True to download the dataset.
Trying fallback dataset: halfcheetah-medium-v2
Failed to load halfcheetah-medium-v2: Dataset halfcheetah-medium-v2 not found locally at C:\Users\32293\.minari\datasets\halfcheetah-medium-v2. Use download=True to download the dataset.
Trying fallback dataset: walker2d-medium-v2
Failed to load walker2d-medium-v2: Dataset walker2d-medium-v2 not found locally at C:\Users\32293\.minari\datasets\walker2d-medium-v2. Use download=True to download the dataset.
Trying fallback dataset: mujoco/pusher/medium-v0
Failed to load mujoco/pusher/medium-v0: Dataset mujoco/pusher/medium-v0 not found locally at C:\Users\32293\.minari\datasets\mujoco\pusher\medium-v0. Use download=True to download the dataset.