2025-09-05 21:49:57,612 INFO    MainThread:3240 [wandb_setup.py:_flush():76] Current SDK version is 0.15.3
2025-09-05 21:49:57,612 INFO    MainThread:3240 [wandb_setup.py:_flush():76] Configure stats pid to 3240
2025-09-05 21:49:57,612 INFO    MainThread:3240 [wandb_setup.py:_flush():76] Loading settings from C:\Users\32293\.config\wandb\settings
2025-09-05 21:49:57,612 INFO    MainThread:3240 [wandb_setup.py:_flush():76] Loading settings from D:\PycharmProjects\MeanFLowTD3\TD3_BC-main\wandb\settings
2025-09-05 21:49:57,612 INFO    MainThread:3240 [wandb_setup.py:_flush():76] Loading settings from environment variables: {}
2025-09-05 21:49:57,613 INFO    MainThread:3240 [wandb_setup.py:_flush():76] Applying setup settings: {'_disable_service': False}
2025-09-05 21:49:57,613 INFO    MainThread:3240 [wandb_setup.py:_flush():76] Inferring run settings from compute environment: {'program_relpath': 'TD3_BC-main\\pure_online_train.py', 'program': 'd:\\PycharmProjects\\MeanFLowTD3\\TD3_BC-main\\pure_online_train.py'}
2025-09-05 21:49:57,614 INFO    MainThread:3240 [wandb_init.py:_log_setup():507] Logging user logs to D:\PycharmProjects\MeanFLowTD3\TD3_BC-main\wandb\run-20250905_214957-5tb9mv00\logs\debug.log
2025-09-05 21:49:57,614 INFO    MainThread:3240 [wandb_init.py:_log_setup():508] Logging internal logs to D:\PycharmProjects\MeanFLowTD3\TD3_BC-main\wandb\run-20250905_214957-5tb9mv00\logs\debug-internal.log
2025-09-05 21:49:57,614 INFO    MainThread:3240 [wandb_init.py:init():547] calling init triggers
2025-09-05 21:49:57,614 INFO    MainThread:3240 [wandb_init.py:init():554] wandb.init called with sweep_config: {}
config: {'policy': 'TD3_BC', 'env': 'mujoco/pusher/expert-v0', 'seed': 0, 'batch_size': 256, 'discount': 0.99, 'tau': 0.005, 'policy_noise': 0.2, 'noise_clip': 0.5, 'policy_freq': 1, 'alpha': 2.5, 'horizon': 1, 'expl_noise': 0.3, 'start_timesteps': 5000.0, 'max_timesteps': 1000000.0, 'eval_freq': 5000.0}
2025-09-05 21:49:57,614 INFO    MainThread:3240 [wandb_init.py:init():596] starting backend
2025-09-05 21:49:57,614 INFO    MainThread:3240 [wandb_init.py:init():600] setting up manager
2025-09-05 21:49:57,627 INFO    MainThread:3240 [backend.py:_multiprocessing_setup():106] multiprocessing start_methods=spawn, using: spawn
2025-09-05 21:49:57,639 INFO    MainThread:3240 [wandb_init.py:init():606] backend started and connected
2025-09-05 21:49:57,646 INFO    MainThread:3240 [wandb_init.py:init():700] updated telemetry
2025-09-05 21:49:58,664 INFO    MainThread:3240 [wandb_init.py:init():737] communicating run to backend with 60.0 second timeout
2025-09-05 21:50:02,115 INFO    Thread-7 (wrapped_target):3240 [retry.py:__call__():172] Retry attempt failed:
Traceback (most recent call last):
  File "C:\Users\32293\.conda\envs\xuance\lib\site-packages\urllib3\connection.py", line 198, in _new_conn
    sock = connection.create_connection(
  File "C:\Users\32293\.conda\envs\xuance\lib\site-packages\urllib3\util\connection.py", line 85, in create_connection
    raise err
  File "C:\Users\32293\.conda\envs\xuance\lib\site-packages\urllib3\util\connection.py", line 73, in create_connection
    sock.connect(sa)
ConnectionRefusedError: [WinError 10061] 由于目标计算机积极拒绝，无法连接。

The above exception was the direct cause of the following exception:

Traceback (most recent call last):
  File "C:\Users\32293\.conda\envs\xuance\lib\site-packages\urllib3\connectionpool.py", line 773, in urlopen
    self._prepare_proxy(conn)
  File "C:\Users\32293\.conda\envs\xuance\lib\site-packages\urllib3\connectionpool.py", line 1042, in _prepare_proxy
    conn.connect()
  File "C:\Users\32293\.conda\envs\xuance\lib\site-packages\urllib3\connection.py", line 704, in connect
    self.sock = sock = self._new_conn()
  File "C:\Users\32293\.conda\envs\xuance\lib\site-packages\urllib3\connection.py", line 213, in _new_conn
    raise NewConnectionError(
urllib3.exceptions.NewConnectionError: <urllib3.connection.HTTPSConnection object at 0x000001F5803063B0>: Failed to establish a new connection: [WinError 10061] 由于目标计算机积极拒绝，无法连接。

The above exception was the direct cause of the following exception:

urllib3.exceptions.ProxyError: ('Unable to connect to proxy', NewConnectionError('<urllib3.connection.HTTPSConnection object at 0x000001F5803063B0>: Failed to establish a new connection: [WinError 10061] 由于目标计算机积极拒绝，无法连接。'))

The above exception was the direct cause of the following exception:

Traceback (most recent call last):
  File "C:\Users\32293\.conda\envs\xuance\lib\site-packages\requests\adapters.py", line 667, in send
    resp = conn.urlopen(
  File "C:\Users\32293\.conda\envs\xuance\lib\site-packages\urllib3\connectionpool.py", line 841, in urlopen
    retries = retries.increment(
  File "C:\Users\32293\.conda\envs\xuance\lib\site-packages\urllib3\util\retry.py", line 519, in increment
    raise MaxRetryError(_pool, url, reason) from reason  # type: ignore[arg-type]
urllib3.exceptions.MaxRetryError: HTTPSConnectionPool(host='api.wandb.ai', port=443): Max retries exceeded with url: /graphql (Caused by ProxyError('Unable to connect to proxy', NewConnectionError('<urllib3.connection.HTTPSConnection object at 0x000001F5803063B0>: Failed to establish a new connection: [WinError 10061] 由于目标计算机积极拒绝，无法连接。')))

During handling of the above exception, another exception occurred:

Traceback (most recent call last):
  File "C:\Users\32293\.conda\envs\xuance\lib\site-packages\wandb\sdk\lib\retry.py", line 131, in __call__
    result = self._call_fn(*args, **kwargs)
  File "C:\Users\32293\.conda\envs\xuance\lib\site-packages\wandb\sdk\internal\internal_api.py", line 285, in execute
    return self.client.execute(*args, **kwargs)  # type: ignore
  File "C:\Users\32293\.conda\envs\xuance\lib\site-packages\wandb\vendor\gql-0.2.0\wandb_gql\client.py", line 52, in execute
    result = self._get_result(document, *args, **kwargs)
  File "C:\Users\32293\.conda\envs\xuance\lib\site-packages\wandb\vendor\gql-0.2.0\wandb_gql\client.py", line 60, in _get_result
    return self.transport.execute(document, *args, **kwargs)
  File "C:\Users\32293\.conda\envs\xuance\lib\site-packages\wandb\sdk\lib\gql_request.py", line 55, in execute
    request = self.session.post(self.url, **post_args)
  File "C:\Users\32293\.conda\envs\xuance\lib\site-packages\requests\sessions.py", line 637, in post
    return self.request("POST", url, data=data, json=json, **kwargs)
  File "C:\Users\32293\.conda\envs\xuance\lib\site-packages\requests\sessions.py", line 589, in request
    resp = self.send(prep, **send_kwargs)
  File "C:\Users\32293\.conda\envs\xuance\lib\site-packages\requests\sessions.py", line 703, in send
    r = adapter.send(request, **kwargs)
  File "C:\Users\32293\.conda\envs\xuance\lib\site-packages\requests\adapters.py", line 694, in send
    raise ProxyError(e, request=request)
requests.exceptions.ProxyError: HTTPSConnectionPool(host='api.wandb.ai', port=443): Max retries exceeded with url: /graphql (Caused by ProxyError('Unable to connect to proxy', NewConnectionError('<urllib3.connection.HTTPSConnection object at 0x000001F5803063B0>: Failed to establish a new connection: [WinError 10061] 由于目标计算机积极拒绝，无法连接。')))
2025-09-05 21:50:59,338 ERROR   MainThread:3240 [wandb_init.py:init():763] encountered error: Run initialization has timed out after 60.0 sec. 
Please refer to the documentation for additional information: https://docs.wandb.ai/guides/track/tracking-faq#initstarterror-error-communicating-with-wandb-process-
2025-09-05 21:51:01,372 ERROR   MainThread:3240 [wandb_init.py:init():1168] Run initialization has timed out after 60.0 sec. 
Please refer to the documentation for additional information: https://docs.wandb.ai/guides/track/tracking-faq#initstarterror-error-communicating-with-wandb-process-
Traceback (most recent call last):
  File "C:\Users\32293\.conda\envs\xuance\lib\site-packages\wandb\sdk\wandb_init.py", line 1150, in init
    run = wi.init()
  File "C:\Users\32293\.conda\envs\xuance\lib\site-packages\wandb\sdk\wandb_init.py", line 769, in init
    raise error
wandb.errors.CommError: Run initialization has timed out after 60.0 sec. 
Please refer to the documentation for additional information: https://docs.wandb.ai/guides/track/tracking-faq#initstarterror-error-communicating-with-wandb-process-
2025-09-05 21:51:02,383 WARNING MsgRouterThr:3240 [router.py:message_loop():77] message_loop has been closed
